<?xml version="1.0"?>
<!-- 
*****************************************************************************************
*
*        =============================================
*                  HB Theme (eYRC 2023-24)
*        =============================================
*
*
*  Filename:            hb_bot.urdf.xacro
*  Created:             Tanishq Chaudhary
*  Last Modified:       27 Sept 2023
*  Author:              Tanishq Chaudhary
*  
*****************************************************************************************
-->


<robot name="hb_bot" xmlns:xacro="http://www.ros.org/wiki/xacro">
    <xacro:include filename="$(find hb_task_1b)/urdf/materials.xacro" />

    <!-- Base Footprint -->
    <link name="base_footprint">
    </link>

    <!-- Base Link -->
    <link name="base_link">
        <inertial>
            <origin xyz="0 0.0 0.28" rpy="0 0 0" />
            <mass value="0.28" />
            <inertia ixx="0.011666666666667" ixy="0" ixz="0" iyy="0.011666666666667" iyz="0" izz="0.011666666666667" />
        </inertial>

        <collision name="collision">
            <origin xyz="0 0.0 0.28" rpy="0 0 0" />
            <geometry>
                <mesh filename="file://$(find hb_task_1b)/meshes/base.dae" scale="0.01  0.01 0.01" />
            </geometry>
        </collision>

        <visual>
            <origin xyz="0 0 0.28" rpy="0 0 0" />
            <geometry>
                <mesh filename="file://$(find hb_task_1b)/meshes/base.dae" scale="0.01  0.01 0.01" />
            </geometry>
        </visual>
    </link>

    <!-- Base Footprint Joint -->
    <joint name="footprint_joint" type="fixed">
        <origin xyz="0.0 0.0 0.0" rpy="0 0 0" />
        <parent link="base_footprint" />
        <child link="base_link" />
    </joint>

    <!-- ########### -->
    <!-- Right Wheel -->
    <link name="right_wheel">
        <inertial>
            <origin xyz="0 -0.05 0.0" rpy="1.57 0 0" />
            <mass value="0.060" />
            <inertia ixx="1.825e-4" ixy="0" ixz="0.00000000" iyy="1.825e-4" iyz="0" izz="1.825e-4" />
        </inertial>

        <collision name="R_collision">
            <origin xyz="0 -0.05 0.0" rpy="1.57 0 0" />
            <geometry>
                <cylinder length="0.13" radius="0.14" />
            </geometry>
        </collision>

        <visual>
            <origin xyz="0.0 0.0 0.0" rpy="0.0 0.0 0.0" />
            <geometry>
                <mesh filename="file://$(find hb_task_1b)/meshes/wheel.stl" scale="5 5 5" />
            </geometry>
        </visual>
    </link>

    <!-- Right Wheel Joint -->
    <joint name="right_wheel_joint" type="continuous">
        <origin xyz="0.0 0.68 0.18" rpy="0 0 0" />
        <parent link="base_link" />
        <child link="right_wheel" />
        <axis xyz="0.0 1.0 0.0" />
        <limit effort="5" velocity="5" />
    </joint>

    <!-- Right Wheel Material Properties -->
    <gazebo reference="right_wheel">
        <material>Gazebo/Black</material>
    </gazebo>

    <!-- ########### -->
    <!-- Left Wheel -->
    <link name="left_wheel">
        <inertial>
            <origin xyz="0 -0.05 0.0" rpy="1.57 0 0" />
            <mass value="0.060" />
            <inertia ixx="1.825e-4" ixy="0" ixz="0.00000000" iyy="1.825e-4" iyz="0" izz="1.825e-4" />
        </inertial>

        <collision name="R_collision">
            <origin xyz="0 -0.05 0.0" rpy="1.57 0 0" />
            <geometry>
                <cylinder length="0.13" radius="0.14" />
            </geometry>
        </collision>

        <visual>
            <origin xyz="0.0 0.0 0.0" rpy="0.0 0.0 0.0" />
            <geometry>
                <mesh filename="file://$(find hb_task_1b)/meshes/wheel.stl" scale="5 5 5" />
            </geometry>
        </visual>
    </link>

    <!-- Left Wheel Joint -->
    <joint name="left_wheel_joint" type="continuous">
        <origin xyz="-0.5 -0.3 0.18" rpy="0 0 -1.046666667" />
        <parent link="base_link" />
        <child link="left_wheel" />
        <axis xyz="0.0 1.0 0.0" />
        <limit effort="5" velocity="5" />
    </joint>

    <!-- Left Wheel Material Properties -->
    <gazebo reference="left_wheel">
        <material>Gazebo/Black</material>
    </gazebo>

    <!-- ########### -->
    <!-- Rear Wheel -->
    <link name="rear_wheel">
        <inertial>
            <origin xyz="0 -0.05 0.0" rpy="1.57 0 0" />
            <mass value="0.060" />
            <inertia ixx="1.825e-4" ixy="0" ixz="0.00000000" iyy="1.825e-4" iyz="0" izz="1.825e-4" />
        </inertial>

        <collision name="R_collision">
            <origin xyz="0 -0.05 0.0" rpy="1.57 0 0" />
            <geometry>
                <cylinder length="0.13" radius="0.14" />
            </geometry>
        </collision>

        <visual>
            <origin xyz="0.0 0.0 0.0" rpy="0.0 0.0 0.0" />
            <geometry>
                <mesh filename="file://$(find hb_task_1b)/meshes/wheel.stl" scale="5 5 5" />
            </geometry>
        </visual>
    </link>

    <!-- Rear Wheel Joint -->
    <joint name="rear_wheel_joint" type="continuous">
        <origin xyz="0.5 -0.3 0.18" rpy="0 0 1.046666667" />
        <parent link="base_link" />
        <child link="rear_wheel" />
        <axis xyz="0.0 1.0 0.0" />
        <limit effort="5" velocity="5" />
    </joint>

    <!-- Rear Wheel Material Properties -->
    <gazebo reference="rear_wheel">
        <material>Gazebo/Black</material>
    </gazebo>

    <!-- ros_control plugin -->

    <gazebo>
        <plugin name="object_controller" filename="libgazebo_ros_planar_move.so">
            <commandTopic>cmd_vel</commandTopic>
            <odometryTopic>odom</odometryTopic>
            <odometryFrame>odom</odometryFrame>
            <odometryRate>20.0</odometryRate>
            <robotBaseFrame>base_link</robotBaseFrame>
        </plugin>
    </gazebo>

</robot>

<!-- One useful hint: the main element that changes from front wheel to left or right wheel is it’s origin. 
    The x and y will change to ±0.15154 and ±0.087275 for the left/right wheels. We’ll let you figure out the 
    roll, pitch, and yaw by yourself. -->